# 47장. 에러처리

## 에러 처리의 필요성

- 에러가 발생하지 않는 코드를 작성하는 것은 불가능하다. 따라서 에러는 언제나 발생할 수 있다.
- 에러나 예외적인 상황에 대응하지 않으면 프로그램은 강제 종료될 것이다.
  - 아무런 조치 없이 강제 종료가 된다면 원인을 파악하여 대응하기 어렵다.
- 따라서 우리가 작성하는 코드에서는 언제나 에러나 예외적인 상황이 발생할 수 있다는 것을 전제하고 이에 대응하는 코드를 작성하는 것이 중요하다.

## try … catch … finally 문

> 일반적으로 에러 처리라 하면 `try … catch … finally` 문을 사용하는 것을 말한다.
>
> `try … catch … finally` 을 사용하면 프로그램이 강제종료 되지 않는다.

- 에러 처리 방식에는 기본적으로 두 가지가 존재한다.
  1.  예외적인 상황이 발생하면 반환하는 값(null 또는 -1)을 if문이나 단축 평가 또는 옵셔널 체이닝 연산자를 통해 확인해서 처리하는 방법
  2.  에러 처리 코드를 미리 등록해 두고 에러가 발생하면 에러 처리 코드로 점프하도록 하는 방법
- `try … catch … finally` 문의 경우 두 번째에 해당한다.
- `try … catch … finally` 는 3개의 코드 블록으로 구성된다.
  ```jsx
  // 구문
  try {
    // 실행할 코드(에러가 발생할 가능성이 있는 코드)
  } catch (err) {
    // try 코드 블록에서 에러가 발생하면 이 코드 블록의 코드가 실행된다.
    // err에는 try 코드 블록에서 발생한 Error 객체가 전달된다.
  } finally {
    // 불필요하다면 생략이 가능하다
    // 에러 발생과 상관없이 반드시 한 번 실행된다
  }
  ```
  - 동작 순서
    - 제일 먼저 `try` 코드 블록이 실행된다.
    - 이때 `try` 코드 블록에 포함된 문 중에서 에러가 발생한다면?
      - 발생한 에러는 `catch`문의 `err` 변수에 전달되고 `catch` 코드 블록이 실행된다.
      - 즉, err 변수는 try 코드 블록에서 에러가 발생한 경우에만 생성되고 catch 문에서만 유효하다
    - finally 코드 블록이 존재한다면 반드시 한 번 실행된다.

## Error 객체

- `Error` 생성자 함수는 에러 객체를 생성한다.
- `Error` 생성자 함수에는 에러를 상세히 설명하는 에러 메시지를 인수로 전달할 수 있다.

```jsx
// 예시
const error = new Error("invalid");
```

- `Error` 생성자 함수가 생성한 에러 객체는 `message` 프로퍼티와 `stack` 프로퍼티를 갖는다.
  - `message` 프로퍼티는 인수로 전달한 에러 메시지이다.
  - `stack` 프로퍼티는 에러를 발생시킨 콜스택의 호출 정보를 나타내는 문자열이다. (디버깅 목적)
- 자바스크립트는 Error 생성자 함수를 포함해 7가지의 Error 생성자 함수를 제공한다.

| 생성자 함수    | 인스턴스                                                                       |
| -------------- | ------------------------------------------------------------------------------ |
| Error          | 일반적 에러 객체                                                               |
| SyntaxError    | 자바스크립트 문법에 맞지 않는 문을 해석할 때 발생하는 에러 객체                |
| ReferenceError | 참조할 수 없는 식별자를 참조했을 때 발생하는 에러 객체                         |
| TypeError      | 피연산자 또는 인수의 데이터 타입이 유효하지 않을 때 발생하는 에러 객체         |
| RangeError     | 숫자값의 허용 범위를 벗어났을 때 발생하는 에러 객체                            |
| URIError       | encodeURI 또는 decodeURI 함수에 부적절한 인수를 전달했을 때 발생하는 에러 객체 |
| EvalError      | eval 함수에서 발생하는 에러 객체                                               |

```jsx
1 @ 1;    // SyntaxError: Invalid or unexpected token
foo();    // ReferenceError: foo is not defined
null.foo; // TypeError: Cannot read property 'foo' of null
new Array(-1); // RangeError: Invalid array length
decodeURIComponent('%'); // URIError: URI malformed
```

## throw 문

- 에러 객체를 생성하면 에러 발생을 해주어야 한다

```jsx
throw 표현식;
```

- throw 문의 표현식은 어떤 값이라도 상관없지만 일반적으로 에러 객체를 지정한다.
- 에러를 던지면 catch 문의 에러 변수가 생성되고 던져진 에러 객체가 할당되고 catch 코드 블록이 실행된다

## 에러의 전파

> **에러는 호출자(`caller`) 방향으로 전파된다.**
> **콜 스택(실행 중인 실행 컨텍스트가 푸시되기 직전에 푸시된 실행 컨텍스트 방향)으로 전파된다**

```jsx
const foo = () => {
  throw Error("foo에서 발생한 에러"); // ④
};

const bar = () => {
  foo(); // ③
};

const baz = () => {
  bar(); // ②
};

try {
  baz(); // ①
} catch (err) {
  console.error(err);
}
```
